Workbook

Sheet Page1
A1: SWANSON PLASTICS (INDIA) PVT. LTD. | K1: FQP-QC02-04
A2: Film Inspection Form | K2: Eff. Date: 01/08/2017
J3: Ref:
A4: Product Code | E4: Prod. Order | G4: Machine | I4: Production Date
A5: Specification | E5: PO | G5: Quantity | I5: Inspection Date
A6: Testing Equipment Identification Number | F6: NA
A7: Sample No. | D7: Film Weight (g/m2) L-17.00 T-18.00 U-20.00 | E7: Thickness (µm) L-18 T-23 U-28 | F7: Wettability (µN/cm) L-360 T-380 U-400 | G7: COF (R-R) L-0.30 T-0.45 U-0.60 | H7: COF (C-C) L-0.60 T- 0.80, U-1.40 | I7: MD
E8: Gauges (microns-µ) | I8: Tensile Break (g/25mm) L-900 U-1200 | J8: Elongation Break (%/25mm) L-350 | K8: 10% Modulus (g/25mm) L-300
A39: Average | D39: =AVERAGE(D9:D38) -> #DIV/0! | E39: =AVERAGE(E9:E38) -> #DIV/0! | F39: =AVERAGE(F9:F38) -> #DIV/0! | G39: =AVERAGE(G9:G38) -> #DIV/0! | H39: =AVERAGE(H9:H38) -> #DIV/0! | I39: =AVERAGE(I9:I38) -> #DIV/0! | J39: =AVERAGE(J9:J38) -> #DIV/0! | K39: =AVERAGE(K9:K38) -> #DIV/0!
A40: Minimum | D40: =MIN(D9:D38) -> 0 | E40: =MIN(E9:E38) -> 0 | F40: =MIN(F9:F38) -> 0 | G40: =MIN(G9:G38) -> 0 | H40: =MIN(H9:H38) -> 0 | I40: =MIN(I9:I38) -> 0 | J40: =MIN(J9:J38) -> 0 | K40: =MIN(K9:K38) -> 0
A41: Maximum | D41: =MAX(D9:D38) -> 0 | E41: =MAX(E9:E38) -> 0 | F41: =MAX(F9:F38) -> 0 | G41: =MAX(G9:G38) -> 0 | H41: =MAX(H9:H38) -> 0 | I41: =MAX(I9:I38) -> 0 | J41: =MAX(J9:J38) -> 0 | K41: =MAX(K9:K38) -> 0
A42: Inspected by: | D42: (QC Inspector) | I42: Verified by: | K42: (QC HOD)
A44: Distribution:Department Concerned | F44: Reference: | G44: 461359700
A45: Retention period: 5 years | K45: Page 1 of 3

Sheet Page2
A1: SWANSON PLASTICS (INDIA) PVT. LTD. | K1: FQP-QC02-04
A2: Film Inspection Form | K2: Eff. Date: 01/08/2017
J3: Ref:
A4: Product Code | B4: =Page1!B4:D4 -> 0 | C4: =Page1!C4 -> 0 | E4: Prod. Order | F4: =Page1!F4 -> 0 | G4: Machine | H4: =Page1!H4 -> 0 | I4: Production Date | J4: =Page1!J4 -> 0
A5: Specification | B5: =Page1!B5:D5 -> 0 | C5: =Page1!C5 -> 0 | E5: PO | F5: =Page1!F5 -> 0 | G5: Quantity | H5: =Page1!H5 -> 0 | I5: Inspection Date | J5: =Page1!J5 -> 0
A6: Testing Equipment Identification Number
A7: Sample No. | D7: CD | G7: Opacity L-45.0 T-50.0 U-55.0 | I7: Roll Cut Width | K7: Diameter (mm) L-410 T-430 U-450
D8: Tensile Break (g/25mm) L-700 U-1000 | E8: Elongation Break (%/25mm) L-400 | F8: 10% Modulus (g/25mm) L-300 | I8: (mm)
I9: T- | J9: 210
I10: U- | J10: 213
A11: =Page1!A9 -> 0 | B11: =Page1!B9 -> 0 | C11: =Page1!C9 -> 0
A12: =Page1!A10 -> 0 | B12: =Page1!B10 -> 0 | C12: =Page1!C10 -> 0
A13: =Page1!A11 -> 0 | B13: =Page1!B11 -> 0 | C13: =Page1!C11 -> 0
A14: =Page1!A12 -> 0 | B14: =Page1!B12 -> 0 | C14: =Page1!C12 -> 0
A15: =Page1!A13 -> 0 | B15: =Page1!B13 -> 0 | C15: =Page1!C13 -> 0
A16: =Page1!A14 -> 0 | B16: =Page1!B14 -> 0 | C16: =Page1!C14 -> 0
A17: =Page1!A15 -> 0 | B17: =Page1!B15 -> 0 | C17: =Page1!C15 -> 0
A18: =Page1!A16 -> 0 | B18: =Page1!B16 -> 0 | C18: =Page1!C16 -> 0
A19: =Page1!A17 -> 0 | B19: =Page1!B17 -> 0 | C19: =Page1!C17 -> 0
A20: =Page1!A18 -> 0 | B20: =Page1!B18 -> 0 | C20: =Page1!C18 -> 0
A21: =Page1!A19 -> 0 | B21: =Page1!B19 -> 0 | C21: =Page1!C19 -> 0
A22: =Page1!A20 -> 0 | B22: =Page1!B20 -> 0 | C22: =Page1!C20 -> 0
... A40: =Page1!A38 -> 0 | B40: =Page1!B38 -> 0 | C40: =Page1!C38 -> 0
A41: Average | D41: =AVERAGE(D11:D40) -> #DIV/0! | E41: =AVERAGE(E11:E40) -> #DIV/0! | F41: =AVERAGE(F11:F40) -> #DIV/0! | G41: =AVERAGE(G11:H40) -> #DIV/0! | I41: =AVERAGE(I11:J40) -> #DIV/0! | K41: =AVERAGE(K11:K40) -> #DIV/0!
A42: Minimum | D42: =MIN(D11:D40) -> 0 | E42: =MIN(E11:E40) -> 0 | F42: =MIN(F11:F40) -> 0 | G42: =MIN(G11:H40) -> 0 | I42: =MIN(I11:J40) -> 0 | K42: =MIN(K11:K40) -> 0
A43: Maximum | D43: =MAX(D11:D40) -> 0 | E43: =MAX(E11:E40) -> 0 | F43: =MAX(F11:F40) -> 0 | G43: =MAX(G11:H40) -> 0 | I43: =MAX(I11:J40) -> 0 | K43: =MAX(K11:K40) -> 0
A44: Inspected by: | D44: (QC Inspector) | I44: Verified by: | K44: (QC HOD)
A46: Distribution:Department Concerned | F46: Reference: | G46: =Page1!G44 -> 461359700
A47: Retention period: 5 years | K47: Page 2 of 3

Sheet Page3
A1: SWANSON PLASTICS (INDIA) PVT. LTD. | K1: FQP-QC02-04
A2: Film Inspection Form | K2: Eff. Date: 01/08/2017
J3: Ref:
A4: Product Code | B4: =Page1!B4:D4 -> 0 | C4: =Page1!C4 -> 0 | E4: Prod. Order | F4: =Page1!F4 -> 0 | G4: Machine | H4: =Page1!H4 -> 0 | I4: Production Date | J4: =Page1!J4 -> 0
A5: Specification | B5: =Page1!B5:D5 -> 0 | C5: =Page1!C5 -> 0 | E5: PO | F5: =Page1!F5 -> 0 | G5: Quantity | H5: =Page1!H5 -> 0 | I5: Inspection Date | J5: =Page1!J5 -> 0
A6: Testing Equipment Identification Number
A7: Sample No. | D7: Printed Ink Film | H7: Delta E (Base Film White) T-0.00 U-5.00
D8: Colour L L-55.00 T-60.00 U-65.00 | E8: Colour A L-45.00 T-50.00 U-55.00 | F8: Colour B L-(-16.00) T-(-11.00) U-(-6.00) | G8: Delta E T-0.00 U-4.00
A10: =Page1!A9 -> 0 | B10: =Page1!B9 -> 0 | C10: =Page1!C9 -> 0
A11: =Page1!A10 -> 0 | B11: =Page1!B10 -> 0 | C11: =Page1!C10 -> 0
A12: =Page1!A11 -> 0 | B12: =Page1!B11 -> 0 | C12: =Page1!C11 -> 0
A13: =Page1!A12 -> 0 | B13: =Page1!B12 -> 0 | C13: =Page1!C12 -> 0
A14: =Page1!A13 -> 0 | B14: =Page1!B13 -> 0 | C14: =Page1!C13 -> 0
A15: =Page1!A14 -> 0 | B15: =Page1!B14 -> 0 | C15: =Page1!C14 -> 0
A16: =Page1!A15 -> 0 | B16: =Page1!B15 -> 0 | C16: =Page1!C15 -> 0
A17: =Page1!A16 -> 0 | B17: =Page1!B16 -> 0 | C17: =Page1!C16 -> 0
A18: =Page1!A17 -> 0 | B18: =Page1!B17 -> 0 | C18: =Page1!C17 -> 0
A19: =Page1!A18 -> 0 | B19: =Page1!B18 -> 0 | C19: =Page1!C18 -> 0
A20: =Page1!A19 -> 0 | B20: =Page1!B19 -> 0 | C20: =Page1!C19 -> 0
A21: =Page1!A20 -> 0 | B21: =Page1!B20 -> 0 | C21: =Page1!C20 -> 0
... A39: =Page1!A38 -> 0 | B39: =Page1!B38 -> 0 | C39: =Page1!C38 -> 0
A40: Average | D40: =AVERAGE(D10:D39) -> #DIV/0! | E40: =AVERAGE(E10:E39) -> #DIV/0! | F40: =AVERAGE(F10:F39) -> #DIV/0! | G40: =AVERAGE(G10:G39) -> #DIV/0! | H40: =AVERAGE(H10:H39) -> #DIV/0!
A41: Minimum | D41: =MIN(D10:D39) -> 0 | E41: =MIN(E10:E39) -> 0 | F41: =MIN(F10:F39) -> 0 | G41: =MIN(G10:G39) -> 0 | H41: =MIN(H10:H39) -> 0
A42: Maximum | D42: =MAX(D10:D39) -> 0 | E42: =MAX(E10:E39) -> 0 | F42: =MAX(F10:F39) -> 0 | G42: =MAX(G10:G39) -> 0 | H42: =MAX(H10:H39) -> 0
A43: Inspected by: | D43: (QC Inspector) | I43: Verified By: | K43: (QC HOD)
A45: Distribution:Department Concerned | F45: Reference: | G45: =Page1!G44 -> 461359700
A46: Retention period: 5 years | K46: Page 3 of 3

Sheet COA Form
A1: FWI-QC13-01
G2: Eff.Date:01/08/2017
A3: Swanson Plastics(India) Pvt. Ltd
A4: Address:Plot No. 2, GIDC, Honda, Bhuipal, Sattari Goa, India 403 530
A5: Certificate of Analysis
A6: Customer: | B6: Unicharm | C6: Machine | D6: =Page1!H4 -> 0 | F6: Production Date | G6: =Page1!J4 -> 0
A7: Lot No. | C7: P/O NO. | D7: =Page1!F5 -> 0
A8: Product Code | B8: =Page1!C4 -> 0 | C8: Quantity | D8: =Page1!H5 -> 0 | F8: Inspection Date | G8: =Page1!J5 -> 0
A9: Material Code | B9: =Page1!G44 -> 461359700 | C9: Embossed | D9: Matte
A10: Product Specification | B10: =Page1!C5 -> 0
A11: Test Items | B11: Unit | C11: Specification | F11: Result | G11: Test Method
C12: LSL | D12: TGT | E12: USL
A13: Film Weight | B13: g/m² | C13: 17 | D13: 18 | E13: 20 | F13: =Page1!D39 -> #DIV/0! | G13: Weighing Scale
A14: Thickness | B14: µm | C14: 18 | D14: 23 | E14: 28 | F14: =Page1!E39 -> #DIV/0! | G14: Thickness Gauge
A15: 10% Modulus-MD | B15: g/25mm | C15: 300 | D15: - | E15: - | F15: =Page1!K39 -> #DIV/0! | G15: UTM
A16: 10% Modulus-CD | B16: g/25mm | C16: 300 | D16: - | E16: - | F16: =Page2!F41 -> #DIV/0!
A17: Tensile Break-MD | B17: g/25mm | C17: 900 | D17: - | E17: 1200 | F17: =Page1!I39 -> #DIV/0!
A18: Tensile Break-CD | B18: g/25mm | C18: 700 | D18: - | E18: 1000 | F18: =Page2!D41 -> #DIV/0!
A19: Elongation-MD | B19: %/25mm | C19: 350 | D19: - | E19: - | F19: =Page1!J39 -> #DIV/0!
A20: Elongation-CD | B20: %/25mm | C20: 400 | D20: - | E20: - | F20: =Page2!E41 -> #DIV/0!
A21: COF (R-R) | B21: - | C21: 0.3 | D21: 0.45 | E21: 0.6 | F21: =Page1!G39 -> #DIV/0!
A22: COF (C-C) | B22: - | C22: 0.6 | D22: 0.8 | E22: 1.4 | F22: =Page1!H39 -> #DIV/0!
A23: Wettability | B23: µN/cm | C23: 360 | D23: 380 | E23: 400 | F23: =Page1!F39 -> #DIV/0! | G23: Dyne Test
A24: Width | B24: mm | C24: - | D24: =Page2!J9 -> 210 | E24: =Page2!J10 -> 213 | F24: =Page2!I41 -> #DIV/0! | G24: Measuring Tape
A25: Roll Length | B25: Meter | C25: 6000 | D25: - | E25: - | F25: 6000 | G25: Length Counter
A26: Roll Diameter | B26: mm | C26: 410 | D26: 430 | E26: 450 | F26: =Page2!K41 -> #DIV/0! | G26: Measuring Tape
A27: Film Appearance
A28: Opacity | C28: LSL-45, TGT-50, USL-55 | F28: O | G28: Spectrophotometer
A29: Glossiness | C29: No Glossy | F29: O | G29: Visual
A30: Colour | C30: Within QC Standard Colour Tolerance | F30: O | G30: Spectrophotometer
A31: Smell | C31: No odd smell | F31: O | G31: Sensory
A32: Colour Fading | C32: No colour fade | F32: O | G32: Visual
A33: Pin Hole | C33: No pin hole is allowed | F33: O | G33: Web Defect Detector
A34: Fish-Eyes | C34: Width < 3 mm Area < 60 Sq. mm | F34: O | G34: Web Defect Detector
A35: Printing
A36: Print Colour | C36: Within QC Standard Colour Tolerance | F36: O | G36: Spectrophotometer
A37: Misprint | C37: 5mmX5mm/m2 (Non-continuous) | F37: O | G37: Visual
A38: Printing dirty | C38: No Dirty Print | F38: O | G38: Visual
A39: Centralisation | C39: ≦ 5 mm from side to printing | F39: O | G39: Measuring Tape
A40: Remarks: | C40: Inspected By | F40: Approved By
...
