Workbook

Sheet Page1
A1: SWANSON PLASTICS (INDIA) PVT. LTD. | I1: FQP-QC02-04
A2: Film Inspection Form | I2: Eff. Date: 01/08/2017
H3: Ref:
A4: Product Code | D4: Prod. Order | F4: Machine | H4: Production Date
A5: Specification | D5: PO | F5: Quantity | H5: Inspection Date
A6: Testing Equipment Identification Number
A7: Sample No. | D7: Film Weight (g/m2) L-15.00 T-16.00 U-18.00 | E7: Thickness (µm) L-32 T-42 U-52 | F7: COF(R-R) L-0.30 T-0.45 U-0.60 | G7: MD
G8: Tensile Break (N/25mm) L-5.00 U-11.00 | H8: Elongation Break (%/25mm) L-350 | I8: 10% Modulus (g/25mm) L-300
A39: Average | D39: =AVERAGE(D9:D38) -> #DIV/0! | E39: =AVERAGE(E9:E38) -> #DIV/0! | F39: =AVERAGE(F9:F38) -> #DIV/0! | G39: =AVERAGE(G9:G38) -> #DIV/0! | H39: =AVERAGE(H9:H38) -> #DIV/0! | I39: =AVERAGE(I9:I38) -> #DIV/0!
A40: Minimum | D40: =MIN(D9:D38) -> 0 | E40: =MIN(E9:E38) -> 0 | F40: =MIN(F9:F38) -> 0 | G40: =MIN(G9:G38) -> 0 | H40: =MIN(H9:H38) -> 0 | I40: =MIN(I9:I38) -> 0
A41: Maximum | D41: =MAX(D9:D38) -> 0 | E41: =MAX(E9:E38) -> 0 | F41: =MAX(F9:F38) -> 0 | G41: =MAX(G9:G38) -> 0 | H41: =MAX(H9:H38) -> 0 | I41: =MAX(I9:I38) -> 0
A42: Inspected by: | D42: (QC Inspector) | G42: Verified by: | I42: (QC HOD)
A44: Distribution:Department Concerned | E44: Reference: | F44: 461343000
A45: Retension period: 5 years | H45: Page 1 of 3

Sheet Page2
A1: SWANSON PLASTICS (INDIA) PVT. LTD. | I1: FQP-QC02-04
A2: Film Inspection Form | I2: Eff. Date: 01/08/2017
H3: Ref: | I3: =Page1!I3 -> 0
A4: Product Code | B4: =Page1!B4 -> 0 | D4: Prod. Order | E4: =Page1!E4 -> 0 | F4: Machine | G4: =Page1!G4 -> 0 | H4: Production Date | I4: =Page1!I4 -> 0
A5: Specification | B5: =Page1!B5 -> 0 | D5: PO | E5: =Page1!E5 -> 0 | F5: Quantity | G5: =Page1!G5 -> 0 | H5: Inspection Date | I5: =Page1!I5 -> 0
A6: Testing Equipment Identification Number
A7: Sample No. | D7: CD | G7: Opacity L-42.0 T-48.0 U-54.0 | H7: Roll Cut Width | I7: Diameter (mm) (L-430 T-460 U-510)
D8: Tensile Break (N/25mm) L-3.00 U-9.00 | E8: Elongation Break (%/25mm) L-400 | F8: 10% Modulus (g/25mm) L-300 | H8: (mm)
H9: T-165
H10: U-168
A41: Average | D41: =AVERAGE(D11:D40) -> #DIV/0! | E41: =AVERAGE(E11:E40) -> #DIV/0! | F41: =AVERAGE(F11:F40) -> #DIV/0! | G41: =AVERAGE(G11:G40) -> #DIV/0! | H41: =AVERAGE(H11:H40) -> #DIV/0! | I41: =AVERAGE(I11:I40) -> #DIV/0!
A42: Minimum | D42: =MIN(D11:D40) -> 0 | E42: =MIN(E11:E40) -> 0 | F42: =MIN(F11:F40) -> 0 | G42: =MIN(G11:G40) -> 0 | H42: =MIN(H11:H40) -> 0 | I42: =MIN(I11:I40) -> 0
A43: Maximum | D43: =MAX(D11:D40) -> 0 | E43: =MAX(E11:E40) -> 0 | F43: =MAX(F11:F40) -> 0 | G43: =MAX(G11:G40) -> 0 | H43: =MAX(H11:H40) -> 0 | I43: =MAX(I11:I40) -> 0
A44: Inspected by: | B44: =Page1!B42 -> 0 | D44: (QC Inspector) | G44: Verified by: | H44: =Page1!H42 -> 0 | I44: (QC HOD)
B45: =Page1!B43 -> 0 | H45: =Page1!H43 -> 0
A46: Distribution:Department Concerned | E46: Reference: | F46: =Page1!F44 -> 461343000
A47: Retension period: 5 years | H47: Page 2 of 3

Sheet Page3
A1: SWANSON PLASTICS (INDIA) PVT. LTD. | I1: FQP-QC02-04
A2: Film Inspection Form | I2: Eff. Date: 01/08/2017
H3: Ref: | I3: =Page1!I3 -> 0
A4: Product Code | B4: =Page1!B4 -> 0 | D4: Prod. Order | E4: =Page1!E4 -> 0 | F4: Machine | G4: =Page1!G4 -> 0 | H4: Production Date | I4: =Page1!I4 -> 0
A5: Specification | B5: =Page1!B5 -> 0 | D5: PO | E5: =Page1!E5 -> 0 | F5: Quantity | G5: =Page1!G5 -> 0 | H5: Inspection Date | I5: =Page1!I5 -> 0
A6: Testing Equipment Identification Number
A7: Sample No. | D7: Colour L (L-90.6 T-94.6 U-98.6) | E7: Colour A (L-(-5.1) T-(-1.1) U-2.9) | F7: Colour B (L-(-3.6) T-0.4 U-4.4) | G7: Delta E (T-0.00 U-5.00)
A39: Average | D39: =AVERAGE(D9:D38) -> #DIV/0! | E39: =AVERAGE(E9:E38) -> #DIV/0! | F39: =AVERAGE(F9:F38) -> #DIV/0! | G39: =AVERAGE(G9:G38) -> #DIV/0!
A40: Minimum | D40: =MIN(D9:D38) -> 0 | E40: =MIN(E9:E38) -> 0 | F40: =MIN(F9:F38) -> 0 | G40: =MIN(G9:G38) -> 0
A41: Maximum | D41: =MAX(D9:D38) -> 0 | E41: =MAX(E9:E38) -> 0 | F41: =MAX(F9:F38) -> 0 | G41: =MAX(G9:G38) -> 0
A42: Inspected by: | B42: =Page1!B42 -> 0 | D42: (QC Inspector) | G42: Verified by: | H42: =Page1!H42 -> 0 | I42: (QC HOD)
B43: =Page1!B43 -> 0 | H43: =Page1!H43 -> 0
A44: Distribution:Department Concerned | E44: Reference: | F44: =Page1!F44 -> 461343000
A45: Retension period: 5 years | H45: Page 3 of 3

Sheet COA Form
A1: FWI-QC13-01
G2: Eff.Date:01/08/2017
A3: Swanson Plastics(India) Pvt. Ltd
A4: Address:Plot No. 2, GIDC, Honda, Bhuipal, Sattari Goa, India 403 530
A5: Certificate of Analysis
A6: Customer: | B6: Unicharm | C6: Machine | D6: #02 | F6: Production Date | G6: =Page1!I4 -> 0
A7: Lot No. | C7: P/O NO. | D7: =Page1!E5 -> 0
A8: Product Code | B8: =Page1!B4 -> 0 | C8: Quantity | D8: =Page1!G5 -> 0 | F8: Inspection Date | G8: =Page1!I5 -> 0
A9: Material Code | B9: =Page1!F44 -> 461343000 | C9: Embossed | D9: Matte
A10: Product Specification | B10: =Page1!B5 -> 0
A11: Test Items | B11: Unit | C11: Specification | F11: Result | G11: Test Method
C12: LSL | D12: TGT | E12: USL
A13: Film Weight | B13: g/m² | C13: 17 | D13: 18 | E13: 20 | F13: =Page1!D39 -> #DIV/0! | G13: Weighing Scale
A14: Thickness | B14: µm | C14: 18 | D14: 23 | E14: 28 | F14: =Page1!E39 -> #DIV/0! | G14: Thickness Gauge
A15: 10% Modulus-MD | B15: g/25mm | C15: 300 | D15: - | E15: - | F15: =Page1!I39 -> #DIV/0! | G15: UTM
A16: 10% Modulus-CD | B16: g/25mm | C16: 300 | D16: - | E16: - | F16: =Page2!F41 -> #DIV/0!
A17: Tensile Break-MD | B17: g/25mm | C17: 900 | D17: - | E17: 1200 | F17: =Page1!G39 -> #DIV/0!
A18: Tensile Break-CD | B18: g/25mm | C18: 700 | D18: - | E18: 1000 | F18: =Page2!D41 -> #DIV/0!
A19: Elongation-MD | B19: %/25mm | C19: 350 | D19: - | E19: - | F19: =Page1!H39 -> #DIV/0!
A20: Elongation-CD | B20: %/25mm | C20: 400 | D20: - | E20: - | F20: =Page2!E41 -> #DIV/0!
A21: COF (R-R) | B21: - | C21: 0.3 | D21: 0.45 | E21: 0.6 | F21: =Page1!F39 -> #DIV/0!
A22: Width | B22: mm | C22: - | D22: 165 | E22: 168 | F22: =Page2!H41 -> #DIV/0! | G22: Measuring Tape
A23: Roll Length | B23: Meter | C23: 6000 | D23: - | E23: - | F23: 6000 | G23: Length Counter
A24: Roll Diameter | B24: mm | C24: 410 | D24: 430 | E24: 450 | F24: =Page2!I41 -> #DIV/0! | G24: Measuring Tape
A25: Film Appearance
A26: Opacity | C26: LSL-45, TGT-50, USL-55 | F26: O | G26: Spectrophotometer
A27: Glossiness | C27: No Glossy | F27: O | G27: Visual
A28: Colour | C28: Within QC Standard Colour Tolerance | F28: O | G28: Spectrophotometer
A29: Smell | C29: No odd smell | F29: O | G29: Sensory
A30: Colour Fading | C30: No colour fade | F30: O | G30: Visual
A31: Pin Hole | C31: No pin hole is allowed | F31: O | G31: Web Defect Detector
A32: Fish-Eyes | C32: Width < 3 mm Area < 60 Sq. mm | F32: O | G32: Web Defect Detector
A33: Printing
A34: Print Colour | C34: Within QC Standard Colour Tolerance | F34: O | G34: Spectrophotometer
A35: Misprint | C35: 5mmX5mm/m2 (Non-continuous) | F35: O | G35: Visual
A36: Printing dirty | C36: No Dirty Print | F36: O | G36: Visual
A37: Centralisation | C37: ≦ 5 mm from side to printing | F37: O | G37: Measuring Tape
A38: Remarks: | C38: Inspected By | F38: Approved By
C40: (QC Inspector) | F40: (QA)
C41: Siddesh Mainkar
...
